TDAT: public void test terminate exception ( ) throws exception {  <NL> swt tester tester = new swt tester ( ) {  <NL>  @ override <NL> public void sut ( ) {  <NL> string [ ] args = { " / terminate " } ;  <NL> entry point . main ( args ) ;  <NL>  }  <NL>  } ;  <NL> wait for shell by name command s = new wait for shell by name command ( ) ;  <NL> s . set shell name ( " login " ) ;  <NL> s . set time out amount ( 5000 ) ;  <NL> try {  <NL> tester . exec command ( s ) ;  <NL> fail ( " terminate exception has to be thrown ! " ) ;  <NL>  } catch ( sut terminated exception e ) {  <NL>  / / that ' s ok , it was terminated <NL>  }  <NL>  }  COM: <s> negative test what happens if we call the sut and sut terminates </s>